Workbook

Sheet 商品一覧
A1: コード | B1: 商品名 | C1: サイト | D1: 正式名称
A2: 63 | B2: のり 大 | C2: アスクル | D2: アスクル オリジナルスティックのり 約22g 1箱（10本入） オリジナル
A3: 46 | B3: 蛍光ペン ブルー | C3: アスクル | D3: 【復活特別価格】アスクル 蛍光ペン 蛍光マーカー シングルタイプ ブルー 1箱（10本入） オリジナル
A4: 15 | B4: A4-Sのび～る | C4: アスクル | D4: プラス のび～るファイル A4S 10冊 AE-50F
A5: 1 | B5: A4-S グレー | C5: アスクル | D5: プラス フラットファイル A4タテ 樹脂製とじ具 グレー 10冊
A6: 32 | B6: 電池 単3 | C6: アスクル | D6: アスクル アルカリ乾電池 単3形 1箱（40本：４本×１０パック）
A7: 44 | B7: 蛍光ペン イエロー | C7: アスクル | D7: 【復活特別価格】アスクル 蛍光ペン 蛍光マーカー シングルタイプ イエロー 黄色 1箱（10本入） オリジナル
A8: 43 | B8: 蛍光ペン ピンク | C8: アスクル | D8: 【復活特別価格】アスクル 蛍光ペン 蛍光マーカー シングルタイプ ピンク 1箱（10本入） オリジナル
A9: 51 | B9: 水性ボールペン 青 | C9: アスクル | D9: （復活感謝祭セール）ゲルインクボールペン サラサクリップ 0.5mm 青 10本 JJ15-BL ゼブラ

Sheet 持出明細表
A1: 事務用品持出明細表
E3: ↓プルダウンから選択 | I3: 塗つぶしセルは自動入力
B4: 年 | C4: 月日 | D4: コード | E4: 商品名 | F4: 仕入 | G4: 使用 | H4: 使用者 | I4: 備考
B5: 2026 | C5: 46074 | D5: =+IF(E5="","",+VLOOKUP(E5,'在庫チェック表(発注担当者用)'!$B$2:$C$77,2,0)) -> 63 | E5: のり 大 | G5: 5 | H5: 木畑
C6: 46076 | D6: =+IF(E6="","",+VLOOKUP(E6,'在庫チェック表(発注担当者用)'!$B$2:$C$77,2,0)) -> 43 | E6: 蛍光ペン ピンク | G6: 10 | H6: 村田
C7: 46077 | D7: =+IF(E7="","",+VLOOKUP(E7,'在庫チェック表(発注担当者用)'!$B$2:$C$77,2,0)) -> 46 | E7: 蛍光ペン ブルー | G7: 8 | H7: 村田
C8: 46086 | D8: =+IF(E8="","",+VLOOKUP(E8,'在庫チェック表(発注担当者用)'!$B$2:$C$77,2,0)) -> 15 | E8: A4-Sのび～る | G8: 3 | H8: 木畑
C9: 46096 | D9: =+IF(E9="","",+VLOOKUP(E9,'在庫チェック表(発注担当者用)'!$B$2:$C$77,2,0)) -> 1 | E9: A4-S グレー | G9: 5 | H9: 木畑
C10: 46112 | D10: =+IF(E10="","",+VLOOKUP(E10,'在庫チェック表(発注担当者用)'!$B$2:$C$77,2,0)) -> 32 | E10: 電池 単3 | G10: 40 | H10: 濱岡
C11: 46112 | D11: =+IF(E11="","",+VLOOKUP(E11,'在庫チェック表(発注担当者用)'!$B$2:$C$77,2,0)) -> 44 | E11: 蛍光ペン イエロー | G11: 2 | H11: 濱岡
C12: 46113 | D12: =+IF(E12="","",+VLOOKUP(E12,'在庫チェック表(発注担当者用)'!$B$2:$C$77,2,0)) -> 43 | E12: 蛍光ペン ピンク | G12: 2 | H12: 濱岡
C13: 46024 | D13: =+IF(E13="","",+VLOOKUP(E13,'在庫チェック表(発注担当者用)'!$B$2:$C$77,2,0)) -> 51 | E13: 水性ボールペン 青 | G13: 2 | H13: 濱岡
D14: =+IF(E14="","",+VLOOKUP(E14,'在庫チェック表(発注担当者用)'!$B$2:$C$77,2,0))
D15: =+IF(E15="","",+VLOOKUP(E15,'在庫チェック表(発注担当者用)'!$B$2:$C$77,2,0))
D16: =+IF(E16="","",+VLOOKUP(E16,'在庫チェック表(発注担当者用)'!$B$2:$C$77,2,0))
D17: =+IF(E17="","",+VLOOKUP(E17,'在庫チェック表(発注担当者用)'!$B$2:$C$77,2,0))
D18: =+IF(E18="","",+VLOOKUP(E18,'在庫チェック表(発注担当者用)'!$B$2:$C$77,2,0))
D19: =+IF(E19="","",+VLOOKUP(E19,'在庫チェック表(発注担当者用)'!$B$2:$C$77,2,0))
D20: =+IF(E20="","",+VLOOKUP(E20,'在庫チェック表(発注担当者用)'!$B$2:$C$77,2,0))
D21: =+IF(E21="","",+VLOOKUP(E21,'在庫チェック表(発注担当者用)'!$B$2:$C$77,2,0))
D22: =+IF(E22="","",+VLOOKUP(E22,'在庫チェック表(発注担当者用)'!$B$2:$C$77,2,0))
D23: =+IF(E23="","",+VLOOKUP(E23,'在庫チェック表(発注担当者用)'!$B$2:$C$77,2,0))
D24: =+IF(E24="","",+VLOOKUP(E24,'在庫チェック表(発注担当者用)'!$B$2:$C$77,2,0))
D25: =+IF(E25="","",+VLOOKUP(E25,'在庫チェック表(発注担当者用)'!$B$2:$C$77,2,0))
... D28: =+IF(E28="","",+VLOOKUP(E28,'在庫チェック表(発注担当者用)'!$B$2:$C$77,2,0))

Sheet 在庫チェック表(発注担当者用)
A1: 在庫マスタ | K1: 発注担当者用シート | M1: ※管理したい項目を増やしたい時は有賀さんに声かける！
B2: 商品名 | C2: NO | D2: 初期在庫 | E2: 発注数 | F2: 残 | G2: 発注判断 | H2: 仕入数 | I2: 使用数 | J2: 発注 基準数 | K2: 備考 | M2: 46059 | N2: カラーインデックス 5山は注文不要。
B3: A4-S グレー | C3: 1 | D3: 11 | E3: 10 | F3: =+D3+H3-I3 -> 6 | G3: =IF(B3=0,"",+IF(F3<=J3,"注文して下さい","")) | H3: =+SUMIF(持出明細表!$D$4:$F$128,C3,持出明細表!$F$4:$F$128) -> 0 | I3: =+SUMIF(持出明細表!$D$4:$G$128,C3,持出明細表!$G$4:$G$128) -> 5 | J3: 3 | N3: =B3 -> A4-S グレー
B4: A4-S厚とじ グレー | C4: 2 | D4: 19 | E4: 10 | F4: =+D4+H4-I4 -> 19 | G4: =IF(B4=0,"",+IF(F4<=J4,"注文して下さい","")) | H4: =+SUMIF(持出明細表!$D$4:$F$128,C4,持出明細表!$F$4:$F$128) -> 0 | I4: =+SUMIF(持出明細表!$D$4:$G$128,C4,持出明細表!$G$4:$G$128) -> 0 | J4: 3 | N4: =B4 -> A4-S厚とじ グレー
B5: A4-S ブルー | C5: 3 | D5: 6 | E5: 10 | F5: =+D5+H5-I5 -> 6 | G5: =IF(B5=0,"",+IF(F5<=J5,"注文して下さい","")) | H5: =+SUMIF(持出明細表!$D$4:$F$128,C5,持出明細表!$F$4:$F$128) -> 0 | I5: =+SUMIF(持出明細表!$D$4:$G$128,C5,持出明細表!$G$4:$G$128) -> 0 | J5: 1 | K5: R3.2月まで在庫管理なし | N5: =B5 -> A4-S ブルー
B6: A4-S ピンク | C6: 4 | D6: 12 | E6: 10 | F6: =+D6+H6-I6 -> 12 | G6: =IF(B6=0,"",+IF(F6<=J6,"注文して下さい","")) | H6: =+SUMIF(持出明細表!$D$4:$F$128,C6,持出明細表!$F$4:$F$128) -> 0 | I6: =+SUMIF(持出明細表!$D$4:$G$128,C6,持出明細表!$G$4:$G$128) -> 0 | J6: 1 | K6: R3.2月まで在庫管理なし | N6: =B6 -> A4-S ピンク
B7: A4-S イエロー | C7: 5 | D7: 5 | E7: 10 | F7: =+D7+H7-I7 -> 5 | G7: =IF(B7=0,"",+IF(F7<=J7,"注文して下さい","")) | H7: =+SUMIF(持出明細表!$D$4:$F$128,C7,持出明細表!$F$4:$F$128) -> 0 | I7: =+SUMIF(持出明細表!$D$4:$G$128,C7,持出明細表!$G$4:$G$128) -> 0 | J7: 1 | K7: R3.2月まで在庫管理なし | N7: =B7 -> A4-S イエロー
B8: A4-S ロイヤルブルー | C8: 6 | D8: 9 | E8: 10 | F8: =+D8+H8-I8 -> 9 | G8: =IF(B8=0,"",+IF(F8<=J8,"注文して下さい","")) | H8: =+SUMIF(持出明細表!$D$4:$F$128,C8,持出明細表!$F$4:$F$128) -> 0 | I8: =+SUMIF(持出明細表!$D$4:$G$128,C8,持出明細表!$G$4:$G$128) -> 0 | J8: 1 | K8: R3.2月まで在庫管理なし | N8: =B8 -> A4-S ロイヤルブルー
B9: A4-S バイオレット | C9: 7 | D9: 5 | E9: 10 | F9: =+D9+H9-I9 -> 5 | G9: =IF(B9=0,"",+IF(F9<=J9,"注文して下さい","")) | H9: =+SUMIF(持出明細表!$D$4:$F$128,C9,持出明細表!$F$4:$F$128) -> 0 | I9: =+SUMIF(持出明細表!$D$4:$G$128,C9,持出明細表!$G$4:$G$128) -> 0 | J9: 1 | K9: R3.2月まで在庫管理なし | N9: =B9 -> A4-S バイオレット
B10: A4-S グリーン | C10: 8 | D10: 2 | E10: 10 | F10: =+D10+H10-I10 -> 2 | G10: =IF(B10=0,"",+IF(F10<=J10,"注文して下さい","")) | H10: =+SUMIF(持出明細表!$D$4:$F$128,C10,持出明細表!$F$4:$F$128) -> 0 | I10: =+SUMIF(持出明細表!$D$4:$G$128,C10,持出明細表!$G$4:$G$128) -> 0 | J10: 1 | K10: R3.2月まで在庫管理なし | N10: =B10 -> A4-S グリーン
B11: A4-E グレー | C11: 9 | D11: 10 | E11: 10 | F11: =+D11+H11-I11 -> 10 | G11: =IF(B11=0,"",+IF(F11<=J11,"注文して下さい","")) | H11: =+SUMIF(持出明細表!$D$4:$F$128,C11,持出明細表!$F$4:$F$128) -> 0 | I11: =+SUMIF(持出明細表!$D$4:$G$128,C11,持出明細表!$G$4:$G$128) -> 0 | J11: 3 | N11: =B11 -> A4-E グレー
B12: A4-E ブルー | C12: 10 | D12: 10 | E12: 10 | F12: =+D12+H12-I12 -> 10 | G12: =IF(B12=0,"",+IF(F12<=J12,"注文して下さい","")) | H12: =+SUMIF(持出明細表!$D$4:$F$128,C12,持出明細表!$F$4:$F$128) -> 0 | I12: =+SUMIF(持出明細表!$D$4:$G$128,C12,持出明細表!$G$4:$G$128) -> 0 | J12: 4 | N12: =B12 -> A4-E ブルー
B13: A4-Eイエローグリーン | C13: 11 | D13: 11 | E13: 10 | F13: =+D13+H13-I13 -> 11 | G13: =IF(B13=0,"",+IF(F13<=J13,"注文して下さい","")) | H13: =+SUMIF(持出明細表!$D$4:$F$128,C13,持出明細表!$F$4:$F$128) -> 0 | I13: =+SUMIF(持出明細表!$D$4:$G$128,C13,持出明細表!$G$4:$G$128) -> 0 | J13: 4 | N13: =B13 -> A4-Eイエローグリーン
B14: A4-E厚とじ イエロー | C14: 12 | D14: 4 | E14: 10 | F14: =+D14+H14-I14 -> 4 | G14: =IF(B14=0,"",+IF(F14<=J14,"注文して下さい","")) | H14: =+SUMIF(持出明細表!$D$4:$F$128,C14,持出明細表!$F$4:$F$128) -> 0 | I14: =+SUMIF(持出明細表!$D$4:$G$128,C14,持出明細表!$G$4:$G$128) -> 0 | J14: 1 | K14: R3.2月まで在庫管理なし | N14: =B14 -> A4-E厚とじ イエロー
B15: A4-E厚とじ イエローグリーン | C15: 13 | D15: 11 | E15: 10 | F15: =+D15+H15-I15 -> 11 | G15: =IF(B15=0,"",+IF(F15<=J15,"注文して下さい","")) | H15: =+SUMIF(持出明細表!$D$4:$F$128,C15,持出明細表!$F$4:$F$128) -> 0 | I15: =+SUMIF(持出明細表!$D$4:$G$128,C15,持出明細表!$G$4:$G$128) -> 0 | J15: 1 | K15: R3.2月まで在庫管理なし | N15: =B15 -> A4-E厚とじ イエローグリーン
B16: A4-E厚とじ グレー | C16: 14 | D16: 12 | E16: 10 | F16: =+D16+H16-I16 -> 12 | G16: =IF(B16=0,"",+IF(F16<=J16,"注文して下さい","")) | H16: =+SUMIF(持出明細表!$D$4:$F$128,C16,持出明細表!$F$4:$F$128) -> 0 | I16: =+SUMIF(持出明細表!$D$4:$G$128,C16,持出明細表!$G$4:$G$128) -> 0 | J16: 1 | K16: R3.2月まで在庫管理なし | N16: =B16 -> A4-E厚とじ グレー
B17: A4-Sのび～る | C17: 15 | D17: 5 | E17: 10 | F17: =+D17+H17-I17 -> 2 | G17: =IF(B17=0,"",+IF(F17<=J17,"注文して下さい","")) -> 注文して下さい | H17: =+SUMIF(持出明細表!$D$4:$F$128,C17,持出明細表!$F$4:$F$128) -> 0 | I17: =+SUMIF(持出明細表!$D$4:$G$128,C17,持出明細表!$G$4:$G$128) -> 3 | J17: 2 | N17: =B17 -> A4-Sのび～る
B18: A4-Eのび～る | C18: 16 | D18: 8 | E18: 10 | F18: =+D18+H18-I18 -> 8 | G18: =IF(B18=0,"",+IF(F18<=J18,"注文して下さい","")) | H18: =+SUMIF(持出明細表!$D$4:$F$128,C18,持出明細表!$F$4:$F$128) -> 0 | I18: =+SUMIF(持出明細表!$D$4:$G$128,C18,持出明細表!$G$4:$G$128) -> 0 | J18: 2 | N18: =B18 -> A4-Eのび～る
B19: B5-S グレー | C19: 17 | D19: 10 | E19: 10 | F19: =+D19+H19-I19 -> 10 | G19: =IF(B19=0,"",+IF(F19<=J19,"注文して下さい","")) | H19: =+SUMIF(持出明細表!$D$4:$F$128,C19,持出明細表!$F$4:$F$128) -> 0 | I19: =+SUMIF(持出明細表!$D$4:$G$128,C19,持出明細表!$G$4:$G$128) -> 0 | J19: 0 | N19: =B19 -> B5-S グレー
B20: B5-S厚とじ ブルー | C20: 18 | D20: 4 | E20: 10 | F20: =+D20+H20-I20 -> 4 | G20: =IF(B20=0,"",+IF(F20<=J20,"注文して下さい","")) | H20: =+SUMIF(持出明細表!$D$4:$F$128,C20,持出明細表!$F$4:$F$128) -> 0 | I20: =+SUMIF(持出明細表!$D$4:$G$128,C20,持出明細表!$G$4:$G$128) -> 0 | J20: 0 | N20: =B20 -> B5-S厚とじ ブルー
B21: B5-E グレー | C21: 19 | D21: 1 | E21: 10 | F21: =+D21+H21-I21 -> 1 | G21: =IF(B21=0,"",+IF(F21<=J21,"注文して下さい","")) | H21: =+SUMIF(持出明細表!$D$4:$F$128,C21,持出明細表!$F$4:$F$128) -> 0 | I21: =+SUMIF(持出明細表!$D$4:$G$128,C21,持出明細表!$G$4:$G$128) -> 0 | J21: 0 | N21: =B21 -> B5-E グレー
B22: B5-E ブルー | C22: 20 | D22: 10 | E22: 10 | F22: =+D22+H22-I22 -> 10 | G22: =IF(B22=0,"",+IF(F22<=J22,"注文して下さい","")) | H22: =+SUMIF(持出明細表!$D$4:$F$128,C22,持出明細表!$F$4:$F$128) -> 0 | I22: =+SUMIF(持出明細表!$D$4:$G$128,C22,持出明細表!$G$4:$G$128) -> 0 | J22: 0 | N22: =B22 -> B5-E ブルー
B23: B5-E イエローグリーン | C23: 21 | D23: 2 | E23: 10 | F23: =+D23+H23-I23 -> 2 | G23: =IF(B23=0,"",+IF(F23<=J23,"注文して下さい","")) | H23: =+SUMIF(持出明細表!$D$4:$F$128,C23,持出明細表!$F$4:$F$128) -> 0 | I23: =+SUMIF(持出明細表!$D$4:$G$128,C23,持出明細表!$G$4:$G$128) -> 0 | J23: 0 | N23: =B23 -> B5-E イエローグリーン
B24: B4-S グレー | C24: 22 | D24: 2 | E24: 10 | F24: =+D24+H24-I24 -> 2 | G24: =IF(B24=0,"",+IF(F24<=J24,"注文して下さい","")) | H24: =+SUMIF(持出明細表!$D$4:$F$128,C24,持出明細表!$F$4:$F$128) -> 0 | I24: =+SUMIF(持出明細表!$D$4:$G$128,C24,持出明細表!$G$4:$G$128) -> 0 | J24: 0 | N24: =B24 -> B4-S グレー
B25: B4-S ブルー | C25: 23 | D25: 14 | E25: 10 | F25: =+D25+H25-I25 -> 14 | G25: =IF(B25=0,"",+IF(F25<=J25,"注文して下さい","")) | H25: =+SUMIF(持出明細表!$D$4:$F$128,C25,持出明細表!$F$4:$F$128) -> 0 | I25: =+SUMIF(持出明細表!$D$4:$G$128,C25,持出明細表!$G$4:$G$128) -> 0 | J25: 0 | K25: R3.2月まで在庫管理なし | N25: =B25 -> B4-S ブルー
B26: B4-E グレー | C26: 24 | D26: 5 | E26: 10 | F26: =+D26+H26-I26 -> 5 | G26: =IF(B26=0,"",+IF(F26<=J26,"注文して下さい","")) | H26: =+SUMIF(持出明細表!$D$4:$F$128,C26,持出明細表!$F$4:$F$128) -> 0 | I26: =+SUMIF(持出明細表!$D$4:$G$128,C26,持出明細表!$G$4:$G$128) -> 0 | J26: 0 | N26: =B26 -> B4-E グレー
B27: B4-E ロイヤルブルー | C27: 25 | D27: 20 | E27: 10 | F27: =+D27+H27-I27 -> 20 | G27: =IF(B27=0,"",+IF(F27<=J27,"注文して下さい","")) | H27: =+SUMIF(持出明細表!$D$4:$F$128,C27,持出明細表!$F$4:$F$128) -> 0 | I27: =+SUMIF(持出明細表!$D$4:$G$128,C27,持出明細表!$G$4:$G$128) -> 0 | J27: 0 | K27: R3.2月まで在庫管理なし | N27: =B27 -> B4-E ロイヤルブルー
B28: B6-E ガバットファイル グレー | C28: 26 | D28: 12 | E28: 10 | F28: =+D28+H28-I28 -> 12 | G28: =IF(B28=0,"",+IF(F28<=J28,"注文して下さい","")) | H28: =+SUMIF(持出明細表!$D$4:$F$128,C28,持出明細表!$F$4:$F$128) -> 0 | I28: =+SUMIF(持出明細表!$D$4:$G$128,C28,持出明細表!$G$4:$G$128) -> 0 | J28: 0 | N28: =B28 -> B6-E ガバットファイル グレー
B29: A3-S グレー | C29: 27 | D29: 2 | E29: 10 | F29: =+D29+H29-I29 -> 2 | G29: =IF(B29=0,"",+IF(F29<=J29,"注文して下さい","")) | H29: =+SUMIF(持出明細表!$D$4:$F$128,C29,持出明細表!$F$4:$F$128) -> 0 | I29: =+SUMIF(持出明細表!$D$4:$G$128,C29,持出明細表!$G$4:$G$128) -> 0 | J29: 0 | N29: =B29 -> A3-S グレー
B30: A3-E グレー | C30: 28 | D30: 11 | E30: 10 | F30: =+D30+H30-I30 -> 11 | G30: =IF(B30=0,"",+IF(F30<=J30,"注文して下さい","")) | H30: =+SUMIF(持出明細表!$D$4:$F$128,C30,持出明細表!$F$4:$F$128) -> 0 | I30: =+SUMIF(持出明細表!$D$4:$G$128,C30,持出明細表!$G$4:$G$128) -> 0 | J30: 0 | N30: =B30 -> A3-E グレー
B31: A5-E グレー | C31: 29 | D31: 5 | E31: 10 | F31: =+D31+H31-I31 -> 5 | G31: =IF(B31=0,"",+IF(F31<=J31,"注文して下さい","")) | H31: =+SUMIF(持出明細表!$D$4:$F$128,C31,持出明細表!$F$4:$F$128) -> 0 | I31: =+SUMIF(持出明細表!$D$4:$G$128,C31,持出明細表!$G$4:$G$128) -> 0 | J31: 0 | N31: =B31 -> A5-E グレー
B32: 電池 単1 | C32: 30 | D32: 14 | E32: 10 | F32: =+D32+H32-I32 -> 14 | G32: =IF(B32=0,"",+IF(F32<=J32,"注文して下さい","")) | H32: =+SUMIF(持出明細表!$D$4:$F$128,C32,持出明細表!$F$4:$F$128) -> 0 | I32: =+SUMIF(持出明細表!$D$4:$G$128,C32,持出明細表!$G$4:$G$128) -> 0 | J32: 2 | N32: =B32 -> 電池 単1
B33: 電池 単2 | C33: 31 | D33: 16 | E33: 10 | F33: =+D33+H33-I33 -> 16 | G33: =IF(B33=0,"",+IF(F33<=J33,"注文して下さい","")) | H33: =+SUMIF(持出明細表!$D$4:$F$128,C33,持出明細表!$F$4:$F$128) -> 0 | I33: =+SUMIF(持出明細表!$D$4:$G$128,C33,持出明細表!$G$4:$G$128) -> 0 | J33: 2 | N33: =B33 -> 電池 単2
B34: 電池 単3 | C34: 32 | D34: 63 | E34: 40 | F34: =+D34+H34-I34 -> 23 | G34: =IF(B34=0,"",+IF(F34<=J34,"注文して下さい","")) -> 注文して下さい | H34: =+SUMIF(持出明細表!$D$4:$F$128,C34,持出明細表!$F$4:$F$128) -> 0 | I34: =+SUMIF(持出明細表!$D$4:$G$128,C34,持出明細表!$G$4:$G$128) -> 40 | J34: 40 | N34: =B34 -> 電池 単3
B35: 電池 単4 | C35: 33 | D35: 70 | E35: 40 | F35: =+D35+H35-I35 -> 70 | G35: =IF(B35=0,"",+IF(F35<=J35,"注文して下さい","")) | H35: =+SUMIF(持出明細表!$D$4:$F$128,C35,持出明細表!$F$4:$F$128) -> 0 | I35: =+SUMIF(持出明細表!$D$4:$G$128,C35,持出明細表!$G$4:$G$128) -> 0 | J35: 8 | N35: =B35 -> 電池 単4
B36: 油性ボールペン 黒 | C36: 34 | D36: 13 | E36: 10 | F36: =+D36+H36-I36 -> 13 | G36: =IF(B36=0,"",+IF(F36<=J36,"注文して下さい","")) | H36: =+SUMIF(持出明細表!$D$4:$F$128,C36,持出明細表!$F$4:$F$128) -> 0 | I36: =+SUMIF(持出明細表!$D$4:$G$128,C36,持出明細表!$G$4:$G$128) -> 0 | J36: 2 | N36: =B36 -> 油性ボールペン 黒
B37: 油性ボールペン 赤 | C37: 35 | D37: 13 | E37: 10 | F37: =+D37+H37-I37 -> 13 | G37: =IF(B37=0,"",+IF(F37<=J37,"注文して下さい","")) | H37: =+SUMIF(持出明細表!$D$4:$F$128,C37,持出明細表!$F$4:$F$128) -> 0 | I37: =+SUMIF(持出明細表!$D$4:$G$128,C37,持出明細表!$G$4:$G$128) -> 0 | J37: 2 | N37: =B37 -> 油性ボールペン 赤
B38: 油性ボールペン 青 | C38: 36 | D38: 8 | E38: 10 | F38: =+D38+H38-I38 -> 8 | G38: =IF(B38=0,"",+IF(F38<=J38,"注文して下さい","")) | H38: =+SUMIF(持出明細表!$D$4:$F$128,C38,持出明細表!$F$4:$F$128) -> 0 | I38: =+SUMIF(持出明細表!$D$4:$G$128,C38,持出明細表!$G$4:$G$128) -> 0 | J38: 2 | N38: =B38 -> 油性ボールペン 青
B39: マッキー極細 黒 | C39: 37 | D39: 23 | E39: 10 | F39: =+D39+H39-I39 -> 23 | G39: =IF(B39=0,"",+IF(F39<=J39,"注文して下さい","")) | H39: =+SUMIF(持出明細表!$D$4:$F$128,C39,持出明細表!$F$4:$F$128) -> 0 | I39: =+SUMIF(持出明細表!$D$4:$G$128,C39,持出明細表!$G$4:$G$128) -> 0 | J39: 1 | N39: =B39 -> マッキー極細 黒
... B69: 修正ペン | C69: 67 | D69: 7 | E69: 10 | F69: =+D69+H69-I69 -> 7 | G69: =IF(B69=0,"",+IF(F69<=J69,"注文して下さい","")) | H69: =+SUMIF(持出明細表!$D$4:$F$128,C69,持出明細表!$F$4:$F$128) -> 0 | I69: =+SUMIF(持出明細表!$D$4:$G$128,C69,持出明細表!$G$4:$G$128) -> 0 | J69: 1 | N69: =B69 -> 修正ペン
...

Sheet 稟議書
A1: 事務用品・消耗品購入稟議書
I2: 注 文 日 | K2: 担当印 | M2: 黄色部分の情報をとってきてほしい
I3: 年 月 日
B4: 購入先 | C4: 商品名 | D4: 個数 | E4: 単価 | F4: 金額 | G4: 新規 | H4: 使用目的 | I4: 依頼者 | J4: 購入可否 | K4: 印
A5: 1 | B5: アスクル | C5: アスクル オリジナルスティックのり 約22g 1箱（10本入） オリジナル | D5: 1 | E5: 1045 | F5: =+D5*E5 -> 1045
A6: 2 | F6: =+D6*E6 -> 0
A7: 3 | F7: =+D7*E7 -> 0
A8: 4 | F8: =+D8*E8 -> 0
A9: 5 | F9: =+D9*E9 -> 0
A10: 6 | F10: =+D10*E10 -> 0
A11: 7 | F11: =+D11*E11 -> 0
A12: 8 | F12: =+D12*E12 -> 0
A13: 9 | F13: =+D13*E13 -> 0
A14: 10 | F14: =+D14*E14 -> 0
A15: 11 | F15: =+D15*E15 -> 0
A16: 12 | F16: =+D16*E16 -> 0
A17: 13 | F17: =+D17*E17 -> 0
... A24: 20 | F24: =+D24*E24 -> 0
